<?xml version="1.0" ?>
<robot name="solo" xmlns:xacro="http://ros.org/wiki/xacro">



  <xacro:property name="color_name" value="grey" />
  <xacro:property name="color" value="0.8 0.8 0.8" />
  <xacro:property name="opacity" value="1.0" />

  <xacro:arg name="flywheel" default="false"/>
  <xacro:arg name="load_force_sensors" default="false"/>


        <xacro:include filename="$(find solo_description)/gazebo/gazebo.urdf.xacro">
             <xacro:arg name="task_period" value="$(arg task_period)"/>
        </xacro:include>


                <!-- Floating-base Joint -->
                <link name="world"/>
                <joint name="floating_base_joint" type="floating">
                    <origin rpy="0 0 0" xyz="0 0 0"/>
                    <parent link="world"/>
                    <child link="base_link"/>
                </joint>

		<link name="base_link" />
                <joint name="floating_base" type="fixed">
                    <origin rpy="0 0 0" xyz="0 0 0"/>
                    <parent link="base_link"/>
                    <child link="trunk"/>
                </joint>

		<link name="trunk">
			<inertial>
			    <origin xyz="0 0 0" rpy="0 0 0" />
			    <mass value="1.63315091"/>
			    <!-- The base is extremely symmetrical. -->
			    <inertia ixx="0.00578574" ixy="0.0" ixz="0.0"
				                      iyy="0.01938108" iyz="0.0"
				                                       izz="0.02476124"/>
			</inertial>
			<visual>
				<origin xyz="0 0 0" rpy="0 0 0" />
				    <geometry>
				      <mesh filename="package://solo_description/meshes/stl/with_foot/solo_body.stl"/>
				    </geometry>
                                    <material name="${color_name}">
				        <color rgba="${color} ${opacity}"/>
				    </material>
			</visual>
			<collision>
		            <origin xyz="0 0 0" rpy="0 0 0" />
		            <geometry>
		              <mesh filename="package://solo_description/meshes/stl/with_foot/solo_body.stl"/>
		            </geometry>
		            <material name="${color_name}">
		                <color rgba="${color} ${opacity}"/>
		            </material>
               		 </collision>
			<!-- Bullet specific paramters -->
		        <contact>
		          <lateral_friction value="1.0"/>
		          <restitution value="0.5"/>
		        </contact>
		</link>






 	 <!-- Include the legs -->
  	<xacro:include filename="$(find solo_description)/urdfs/leg.xacro"/>



        <!-- Include flywheel -->
        <xacro:if value="$(arg flywheel)">
              <xacro:include filename="$(find solo_description)/urdfs/flywheel.xacro"/>
              <!-- inertia = 0.5 m*radius^2 but I had to set 10 times more for sm stability-->
              <xacro:flywheel_train radius="0.05" mass_lr="0.2" inertia_lr="0.0025"  mass_fh="0.2" inertia_fh="0.0025"/>
        </xacro:if>






  <!-- Include the front left leg -->
  <xacro:leg
      prefix="lf"
      is_front="true"
      is_right="false"
      has_side_motion="true"
      color_name="${color_name}"
      color="${color}"
      opacity="${opacity}"
      load_force_sensors="$(arg load_force_sensors)"/>

  <!-- Include the front right leg -->
  <xacro:leg
      prefix="rf"
      is_front="true"
      is_right="true"
      has_side_motion="true"
      color_name="${color_name}"
      color="${color}"
      opacity="${opacity}"
      load_force_sensors="$(arg load_force_sensors)"/>

  <!-- Include the hind left leg -->
  <xacro:leg
      prefix="lh"
      is_front="false"
      is_right="false"
      has_side_motion="true"
      color_name="${color_name}"
      color="${color}"
      opacity="${opacity}"
      load_force_sensors="$(arg load_force_sensors)"/>

  <!-- Include the hind right leg -->
  <xacro:leg
      prefix="rh"
      is_front="false"
      is_right="true"
      has_side_motion="true"
      color_name="${color_name}"
      color="${color}"
      opacity="${opacity}"
      load_force_sensors="$(arg load_force_sensors)"/>
</robot>
